Ignoring exception in on_message
Traceback (most recent call last):
  File "/home/ubuntu/.local/lib/python3.8/site-packages/discord/ext/commands/bot.py", line 939, in invoke
    await ctx.command.invoke(ctx)
  File "/home/ubuntu/.local/lib/python3.8/site-packages/discord/ext/commands/core.py", line 855, in invoke
    await self.prepare(ctx)
  File "/home/ubuntu/.local/lib/python3.8/site-packages/discord/ext/commands/core.py", line 789, in prepare
    await self._parse_arguments(ctx)
  File "/home/ubuntu/.local/lib/python3.8/site-packages/discord/ext/commands/core.py", line 706, in _parse_arguments
    kwargs[name] = await self.transform(ctx, param)
  File "/home/ubuntu/.local/lib/python3.8/site-packages/discord/ext/commands/core.py", line 542, in transform
    raise MissingRequiredArgument(param)
discord.ext.commands.errors.MissingRequiredArgument: args is a required argument that is missing.

During handling of the above exception, another exception occurred:

Traceback (most recent call last):
  File "/home/ubuntu/.local/lib/python3.8/site-packages/discord/ext/commands/core.py", line 71, in wrapped
    ret = await coro(*args, **kwargs)
  File "/home/ubuntu/RoleManager/src/main.py", line 104, in create_error
    if isinstance(error, commands.CheckFailure):
AttributeError: 'Command' object has no attribute 'CheckFailure'

The above exception was the direct cause of the following exception:

Traceback (most recent call last):
  File "/home/ubuntu/.local/lib/python3.8/site-packages/discord/client.py", line 343, in _run_event
    await coro(*args, **kwargs)
  File "/home/ubuntu/.local/lib/python3.8/site-packages/discord/ext/commands/bot.py", line 979, in on_message
    await self.process_commands(message)
  File "/home/ubuntu/.local/lib/python3.8/site-packages/discord/ext/commands/bot.py", line 976, in process_commands
    await self.invoke(ctx)
  File "/home/ubuntu/.local/lib/python3.8/site-packages/discord/ext/commands/bot.py", line 943, in invoke
    await ctx.command.dispatch_error(ctx, exc)
  File "/home/ubuntu/.local/lib/python3.8/site-packages/discord/ext/commands/core.py", line 424, in dispatch_error
    await injected(ctx, error)
  File "/home/ubuntu/.local/lib/python3.8/site-packages/discord/ext/commands/core.py", line 77, in wrapped
    raise CommandInvokeError(exc) from exc
discord.ext.commands.errors.CommandInvokeError: Command raised an exception: AttributeError: 'Command' object has no attribute 'CheckFailure'
Logged in as RoleManager#3070 (ID: 864559239187529749)
